Workbook

Sheet Summary
A1: KrystalHR Super Admin (Staging) - System Test Report
A3: Environment | B3: https://admin.krystalhrsite.kdns.site
A4: Test account | B4: tester@krystalhr.com (Super Admin)
A5: Modules in scope | B5: Dashboard, Organization, Sign Up, Announcements (+ login and cross-module checks)
A6: Test level / approach | B6: System testing: exploratory session, then an automated Cypress suite that re-checks every scenario
A7: Email verification | B7: /log-viewer > laravel-{date}.log (as instructed in the assessment brief)
A8: Tested by | B8: Michael Chilaka
A9: Executed | B9: 2026-10-09 15:54 UTC to 2026-10-09 16:03 UTC
A10: Tooling | B10: Cypress 15.21.1 on Chrome, 1280x720
A12: Overall result
A13: Test cases | B13: Executed | C13: Passed | D13: Failed | E13: Not run | F13: Pass rate | G13: Defects | H13: Critical | I13: High | J13: Medium | K13: Low
A14: =COUNTA('Test Cases'!$A$2:$A$97) -> 96 | B14: =C14+D14 -> 96 | C14: =COUNTIF('Test Cases'!$I$2:$I$97,"PASS") -> 61 | D14: =COUNTIF('Test Cases'!$I$2:$I$97,"FAIL") -> 35 | E14: =COUNTIF('Test Cases'!$I$2:$I$97,"NOT RUN") -> 0 | F14: =IF(B14=0,0,C14/B14) -> 0.63541667 | G14: =COUNTA('Defect Log'!$A$2:$A$40) -> 39 | H14: =COUNTIF('Defect Log'!$E$2:$E$40,"Critical") -> 1 | I14: =COUNTIF('Defect Log'!$E$2:$E$40,"High") -> 6 | J14: =COUNTIF('Defect Log'!$E$2:$E$40,"Medium") -> 14 | K14: =COUNTIF('Defect Log'!$E$2:$E$40,"Low") -> 18
A16: Result by module
A17: Module | B17: Test cases | C17: Passed | D17: Failed | E17: Not run | F17: Pass rate | G17: Defects | H17: Critical | I17: High | J17: Medium | K17: Low
A18: Dashboard | B18: =COUNTIF('Test Cases'!$B$2:$B$97,A18) -> 12 | C18: =COUNTIFS('Test Cases'!$B$2:$B$97,A18,'Test Cases'!$I$2:$I$97,"PASS") -> 9 | D18: =COUNTIFS('Test Cases'!$B$2:$B$97,A18,'Test Cases'!$I$2:$I$97,"FAIL") -> 3 | E18: =COUNTIFS('Test Cases'!$B$2:$B$97,A18,'Test Cases'!$I$2:$I$97,"NOT RUN") -> 0 | F18: =IF(C18+D18=0,0,C18/(C18+D18)) -> 0.75 | G18: =COUNTIF('Defect Log'!$B$2:$B$40,A18) -> 2 | H18: =COUNTIFS('Defect Log'!$B$2:$B$40,A18,'Defect Log'!$E$2:$E$40,"Critical") -> 0 | I18: =COUNTIFS('Defect Log'!$B$2:$B$40,A18,'Defect Log'!$E$2:$E$40,"High") -> 0 | J18: =COUNTIFS('Defect Log'!$B$2:$B$40,A18,'Defect Log'!$E$2:$E$40,"Medium") -> 2 | K18: =COUNTIFS('Defect Log'!$B$2:$B$40,A18,'Defect Log'!$E$2:$E$40,"Low") -> 0
A19: Organization | B19: =COUNTIF('Test Cases'!$B$2:$B$97,A19) -> 37 | C19: =COUNTIFS('Test Cases'!$B$2:$B$97,A19,'Test Cases'!$I$2:$I$97,"PASS") -> 18 | D19: =COUNTIFS('Test Cases'!$B$2:$B$97,A19,'Test Cases'!$I$2:$I$97,"FAIL") -> 19 | E19: =COUNTIFS('Test Cases'!$B$2:$B$97,A19,'Test Cases'!$I$2:$I$97,"NOT RUN") -> 0 | F19: =IF(C19+D19=0,0,C19/(C19+D19)) -> 0.48648649 | G19: =COUNTIF('Defect Log'!$B$2:$B$40,A19) -> 23 | H19: =COUNTIFS('Defect Log'!$B$2:$B$40,A19,'Defect Log'!$E$2:$E$40,"Critical") -> 0 | I19: =COUNTIFS('Defect Log'!$B$2:$B$40,A19,'Defect Log'!$E$2:$E$40,"High") -> 4 | J19: =COUNTIFS('Defect Log'!$B$2:$B$40,A19,'Defect Log'!$E$2:$E$40,"Medium") -> 7 | K19: =COUNTIFS('Defect Log'!$B$2:$B$40,A19,'Defect Log'!$E$2:$E$40,"Low") -> 12
A20: Sign Up | B20: =COUNTIF('Test Cases'!$B$2:$B$97,A20) -> 15 | C20: =COUNTIFS('Test Cases'!$B$2:$B$97,A20,'Test Cases'!$I$2:$I$97,"PASS") -> 7 | D20: =COUNTIFS('Test Cases'!$B$2:$B$97,A20,'Test Cases'!$I$2:$I$97,"FAIL") -> 8 | E20: =COUNTIFS('Test Cases'!$B$2:$B$97,A20,'Test Cases'!$I$2:$I$97,"NOT RUN") -> 0 | F20: =IF(C20+D20=0,0,C20/(C20+D20)) -> 0.46666667 | G20: =COUNTIF('Defect Log'!$B$2:$B$40,A20) -> 9 | H20: =COUNTIFS('Defect Log'!$B$2:$B$40,A20,'Defect Log'!$E$2:$E$40,"Critical") -> 0 | I20: =COUNTIFS('Defect Log'!$B$2:$B$40,A20,'Defect Log'!$E$2:$E$40,"High") -> 2 | J20: =COUNTIFS('Defect Log'!$B$2:$B$40,A20,'Defect Log'!$E$2:$E$40,"Medium") -> 3 | K20: =COUNTIFS('Defect Log'!$B$2:$B$40,A20,'Defect Log'!$E$2:$E$40,"Low") -> 4
A21: Announcements | B21: =COUNTIF('Test Cases'!$B$2:$B$97,A21) -> 19 | C21: =COUNTIFS('Test Cases'!$B$2:$B$97,A21,'Test Cases'!$I$2:$I$97,"PASS") -> 15 | D21: =COUNTIFS('Test Cases'!$B$2:$B$97,A21,'Test Cases'!$I$2:$I$97,"FAIL") -> 4 | E21: =COUNTIFS('Test Cases'!$B$2:$B$97,A21,'Test Cases'!$I$2:$I$97,"NOT RUN") -> 0 | F21: =IF(C21+D21=0,0,C21/(C21+D21)) -> 0.78947368 | G21: =COUNTIF('Defect Log'!$B$2:$B$40,A21) -> 4 | H21: =COUNTIFS('Defect Log'!$B$2:$B$40,A21,'Defect Log'!$E$2:$E$40,"Critical") -> 0 | I21: =COUNTIFS('Defect Log'!$B$2:$B$40,A21,'Defect Log'!$E$2:$E$40,"High") -> 0 | J21: =COUNTIFS('Defect Log'!$B$2:$B$40,A21,'Defect Log'!$E$2:$E$40,"Medium") -> 2 | K21: =COUNTIFS('Defect Log'!$B$2:$B$40,A21,'Defect Log'!$E$2:$E$40,"Low") -> 2
A22: Authentication | B22: =COUNTIF('Test Cases'!$B$2:$B$97,A22) -> 8 | C22: =COUNTIFS('Test Cases'!$B$2:$B$97,A22,'Test Cases'!$I$2:$I$97,"PASS") -> 8 | D22: =COUNTIFS('Test Cases'!$B$2:$B$97,A22,'Test Cases'!$I$2:$I$97,"FAIL") -> 0 | E22: =COUNTIFS('Test Cases'!$B$2:$B$97,A22,'Test Cases'!$I$2:$I$97,"NOT RUN") -> 0 | F22: =IF(C22+D22=0,0,C22/(C22+D22)) -> 1 | G22: =COUNTIF('Defect Log'!$B$2:$B$40,A22) -> 0 | H22: =COUNTIFS('Defect Log'!$B$2:$B$40,A22,'Defect Log'!$E$2:$E$40,"Critical") -> 0 | I22: =COUNTIFS('Defect Log'!$B$2:$B$40,A22,'Defect Log'!$E$2:$E$40,"High") -> 0 | J22: =COUNTIFS('Defect Log'!$B$2:$B$40,A22,'Defect Log'!$E$2:$E$40,"Medium") -> 0 | K22: =COUNTIFS('Defect Log'!$B$2:$B$40,A22,'Defect Log'!$E$2:$E$40,"Low") -> 0
A23: Cross-module | B23: =COUNTIF('Test Cases'!$B$2:$B$97,A23) -> 5 | C23: =COUNTIFS('Test Cases'!$B$2:$B$97,A23,'Test Cases'!$I$2:$I$97,"PASS") -> 4 | D23: =COUNTIFS('Test Cases'!$B$2:$B$97,A23,'Test Cases'!$I$2:$I$97,"FAIL") -> 1 | E23: =COUNTIFS('Test Cases'!$B$2:$B$97,A23,'Test Cases'!$I$2:$I$97,"NOT RUN") -> 0 | F23: =IF(C23+D23=0,0,C23/(C23+D23)) -> 0.8 | G23: =COUNTIF('Defect Log'!$B$2:$B$40,A23) -> 1 | H23: =COUNTIFS('Defect Log'!$B$2:$B$40,A23,'Defect Log'!$E$2:$E$40,"Critical") -> 1 | I23: =COUNTIFS('Defect Log'!$B$2:$B$40,A23,'Defect Log'!$E$2:$E$40,"High") -> 0 | J23: =COUNTIFS('Defect Log'!$B$2:$B$40,A23,'Defect Log'!$E$2:$E$40,"Medium") -> 0 | K23: =COUNTIFS('Defect Log'!$B$2:$B$40,A23,'Defect Log'!$E$2:$E$40,"Low") -> 0
A24: Total | B24: =SUM(B18:B23) -> 96 | C24: =SUM(C18:C23) -> 61 | D24: =SUM(D18:D23) -> 35 | E24: =SUM(E18:E23) -> 0 | F24: =IF(C24+D24=0,0,C24/(C24+D24)) -> 0.63541667 | G24: =SUM(G18:G23) -> 39 | H24: =SUM(H18:H23) -> 1 | I24: =SUM(I18:I23) -> 6 | J24: =SUM(J18:J23) -> 14 | K24: =SUM(K18:K23) -> 18
A26: Assessment
A27: The core flows work: login and session handling, listing / searching organizations, creating an organization, activating and suspending it, editing its details, adding admins, CSV export / template / import validation, contacting and approving a sign-up, and composing, sending and viewing an announcement, with the emails arriving in the log. Server-side validation is generally thorough and HTML input is escaped or sanitised.
A28: 39 defects were logged. The build should not be released until the Critical and High items below are fixed: the log viewer exposes every outgoing email (including admin passwords) to anonymous visitors, a sign-up cannot be rejected, an organization's plan cannot be changed, and the Add Organization form can fail without telling the user why.
A30: Critical and High defects (details in 'Defect Log')
A31: Defect ID | B31: Severity | C31: Module | D31: Summary
A32: BUG-001 | B32: Critical | C32: Cross-module | D32: Server logs (including emails with admin passwords) can be read without logging in
A33: BUG-002 | B33: High | C33: Organization | D33: Admin password is emailed in plain text and is predictable (first name + last 4 phone digits)
A34: BUG-003 | B34: High | C34: Sign Up | D34: 'Reject' in the Review dialog does nothing
A35: BUG-004 | B35: High | C35: Organization | D35: Add Organization fails silently when the Domain Prefix is invalid (error is never displayed)
A36: BUG-005 | B36: High | C36: Organization | D36: 'Change Plan' cannot be saved
A37: BUG-006 | B37: High | C37: Organization | D37: The same organization appears on several pages of the list while others are skipped
A38: BUG-007 | B38: High | C38: Sign Up | D38: A pending (unapproved) organization already receives the welcome email and admin login credentials

Sheet Test Cases
A1: Test ID | B1: Module | C1: Type | D1: Priority | E1: Scenario | F1: Steps | G1: Expected Result | H1: Actual Result | I1: Status | J1: Defect ID | K1: Duration (s)
A2: AUTH-001 | B2: Authentication | C2: UI | D2: High | E2: Login page shows email, password and Log in controls | F2: 1. Open /auth/login while logged out. | G2: Email field, password field, 'Remember me', 'Forgot your password?' and a 'Log in' button are displayed. | H2: As expected. | I2: PASS | K2: 3.1
A3: AUTH-002 | B3: Authentication | C3: Functional | D3: High | E3: Valid assessment credentials log in to the dashboard | F3: 1. Open /auth/login. 2. Enter tester@krystalhr.com / pass0403. 3. Click 'Log in'. | G3: User lands on /dashboard and the side menu is shown. | H3: As expected. | I3: PASS | K3: 3.5
A4: AUTH-003 | B4: Authentication | C4: Negative | D4: High | E4: Wrong password is rejected with a generic error | F4: 1. Open /auth/login. 2. Enter the valid email and a wrong password. 3. Click 'Log in'. | G4: User stays on the login page and sees 'These credentials do not match our records.' | H4: As expected. | I4: PASS | K4: 2.4
A5: AUTH-004 | B5: Authentication | C5: Security | D5: Medium | E5: Unknown email gets the same generic error (no account enumeration) | F5: 1. Open /auth/login. 2. Enter an email that has no account and any password. 3. Click 'Log in'. | G5: Same generic error as a wrong password; nothing reveals whether the account exists. | H5: As expected. | I5: PASS | K5: 2.7
A6: AUTH-005 | B6: Authentication | C6: Validation | D6: Medium | E6: Empty login form is blocked by required-field validation | F6: 1. Open /auth/login. 2. Click 'Log in' without typing anything. | G6: Form is not submitted; the email field is flagged as required. | H6: As expected. | I6: PASS | K6: 1.1
A7: AUTH-006 | B7: Authentication | C7: Security | D7: High | E7: Module pages redirect to login when not authenticated | F7: 1. Without a session request /dashboard, /organizations, /sign-ups, /announcements and /announcements/create. | G7: Each request is redirected (302) to /auth/login. | H7: As expected. | I7: PASS | K7: 1.7
A8: AUTH-007 | B8: Authentication | C8: Functional | D8: High | E8: Log Out ends the session | F8: 1. Log in. 2. Open the user menu and click 'Log Out'. 3. Open /dashboard again. | G8: User is returned to the login page and /dashboard is no longer reachable. | H8: As expected. | I8: PASS | K8: 6.1
A9: AUTH-008 | B9: Authentication | C9: Security | D9: Medium | E9: Forgot password gives the same response for known and unknown emails | F9: 1. Open /auth/forgot-password. 2. Submit an unknown email. 3. Submit the tester email. | G9: Both show 'A reset link will be sent if the account exists.' | H9: As expected. | I9: PASS | K9: 3.2
A10: DSH-001 | B10: Dashboard | C10: UI | D10: High | E10: Dashboard shows the three KPI cards with numeric values | F10: 1. Log in and open /dashboard. | G10: 'Total Organizations', 'Pending Organizations' and 'Total Users' cards each show a whole number. | H10: As expected. | I10: PASS | K10: 6.7
A11: DSH-002 | B11: Dashboard | C11: Functional | D11: High | E11: Side menu lists the four modules and each link opens its page | F11: 1. Open /dashboard. 2. Click Organizations, Sign Ups, Announcements and Dashboard in the side menu. | G11: Each click opens /organizations, /sign-ups, /announcements and /dashboard respectively. | H11: As expected. | I11: PASS | K11: 3.8
A12: DSH-003 | B12: Dashboard | C12: Data integrity | D12: High | E12: 'Total Organizations' matches the number of records in the organization list | F12: 1. Note 'Total Organizations' on the dashboard. 2. Open the last page of /organizations. 3. Compute (last page - 1) x 10 + rows on the last page. | G12: The computed record count equals the KPI card. | H12: As expected. | I12: PASS | K12: 4.3
A13: DSH-004 | B13: Dashboard | C13: Data integrity | D13: High | E13: 'Pending Organizations' matches the number of pending sign-ups | F13: 1. Note 'Pending Organizations' on the dashboard. 2. Open the last page of /sign-ups and count all records. | G13: The number of sign-up records equals the KPI card. | H13: As expected. | I13: PASS | K13: 3.7
A14: DSH-005 | B14: Dashboard | C14: Data integrity | D14: Medium | E14: Organization Status chart is consistent with the KPI cards | F14: 1. Open /dashboard. 2. Read the Active / Pending / Suspended shares used by the doughnut chart. | G14: Shares add up to 100% and the Pending share equals Pending / Total from the cards. | H14: As expected. | I14: PASS | K14: 2.6
A15: DSH-006 | B15: Dashboard | C15: UI | D15: Medium | E15: KPI trend badges show a unit and are specific to each card | F15: 1. Open /dashboard. 2. Read the green trend badge on 'Total Organizations' and 'Pending Organizations'. | G15: Each badge shows a value with a unit (e.g. %) calculated for its own metric. | H15: Both badges show the identical value with no unit or period. The value follows the total (1870.83 at 946 organizations, 1879.17 at 950), so the Pending card displays the Total card's growth. 'Total Users' has no badge. Automated check: AssertionError: Total Organizations trend badge: expected '1904.17' to match /%/ | I15: FAIL | J15: BUG-014 | K15: 1.7
A16: DSH-007 | B16: Dashboard | C16: Data integrity | D16: Medium | E16: 'Action Required' alerts refer to real organizations | F16: 1. Open /dashboard. 2. Read the organization names listed under 'Action Required'. 3. Search each name in the Companies table. | G16: Every alert refers to an organization that exists in the system. | H16: The panel always lists 'Global Marketing', 'Product Launch' and 'Customer Support' (3 / 5 / 10 days). None of them exists as an organization. 'View all' has no action: no navigation, dialog or request. Automated check: AssertionError: alert names that match no organization: expected [ Array(3) ] to deeply equal [] | I16: FAIL | J16: BUG-015 | K16: 5.9
A17: DSH-008 | B17: Dashboard | C17: Functional | D17: Medium | E17: 'View all' in Action Required opens the full list of alerts | F17: 1. Open /dashboard. 2. Click 'View all' in the Action Required panel. | G17: A page, modal or expanded list with all alerts is shown. | H17: The panel always lists 'Global Marketing', 'Product Launch' and 'Customer Support' (3 / 5 / 10 days). None of them exists as an organization. 'View all' has no action: no navigation, dialog or request. Automated check: AssertionError: 'View all' navigated, opened a dialog or expanded the list: expected false to equal true | I17: FAIL | J17: BUG-015 | K17: 3.8
A18: DSH-009 | B18: Dashboard | C18: UI | D18: High | E18: Companies table on the dashboard shows its columns and ten rows | F18: 1. Open /dashboard. 2. Scroll to 'Companies'. | G18: Columns Organizations, Plan, Sign Up Date, Employees, Date Updated, Status, Action are shown with 10 rows and pagination. | H18: As expected. | I18: PASS | K18: 1.5
A19: DSH-010 | B19: Dashboard | C19: Functional | D19: Medium | E19: Dashboard search filters companies and shows an empty-state message | F19: 1. On /dashboard type the name of the first company in Search. 2. Replace it with a string that matches nothing. | G19: Only matching companies are listed; with no match 'No companies found.' is shown. | H19: As expected. | I19: PASS | K19: 4.6
A20: DSH-011 | B20: Dashboard | C20: UI | D20: Low | E20: Light / dark appearance toggle switches the theme | F20: 1. Open /dashboard. 2. Click the dark (moon) option in the header. 3. Click the light (sun) option. | G20: The page switches to the dark theme and back to the light theme. | H20: As expected. | I20: PASS | K20: 1.7
A21: DSH-012 | B21: Dashboard | C21: Functional | D21: Medium | E21: 'Add Organization' can be opened from the dashboard | F21: 1. Open /dashboard. 2. Click 'Add Organization'. | G21: The 'Add New Organization' form opens. | H21: As expected. | I21: PASS | K21: 1.8
A22: ORG-001 | B22: Organization | C22: UI | D22: High | E22: Organizations page lists companies with columns, actions and pagination | F22: 1. Open /organizations. | G22: Ten rows with Plan, dates, Status badge, Activate/Suspend and Manage actions, plus pagination, Search, Export CSV, Import CSV and Sort. | H22: As expected. | I22: PASS | K22: 2.8
A23: ORG-002 | B23: Organization | C23: Functional | D23: High | E23: Search finds an organization regardless of letter case | F23: 1. Open /organizations. 2. Search the test organization's name in lower case. 3. Search a string that matches nothing. | G23: The organization is listed; the non-matching search shows 'No companies found.' | H23: As expected. | I23: PASS | K23: 4.3
A24: ORG-003 | B24: Organization | C24: Functional | D24: Low | E24: Search ignores leading and trailing spaces | F24: 1. Open /organizations. 2. Search the test organization's name with two spaces before and after it. | G24: The organization is still found. | H24: 'No companies found.' Same behaviour in Sign Ups and Announcements. Also, '%' is treated as a wildcard and returns every record. Automated check: AssertionError: organizations found: expected [] to deeply equal [ '1012' ] | I24: FAIL | J24: BUG-022 | K24: 2.8
A25: ORG-004 | B25: Organization | C25: Functional | D25: Medium | E25: Sort by Oldest lists the earliest sign-ups first | F25: 1. Open /organizations. 2. Choose Sort by > Oldest. | G25: Rows are ordered by Sign Up Date ascending. | H25: As expected. | I25: PASS | K25: 3.5
A26: ORG-005 | B26: Organization | C26: Functional | D26: Low | E26: Sort by Name lists organizations alphabetically | F26: 1. Open /organizations. 2. Choose Sort by > Name. 3. Read the names of the rows that start with a letter. | G26: Names are in ascending alphabetical order. | H26: 'Ewing Manning Co' and 'Ruby & Topaz' are listed before 'Abdullahi Systems'. The export shows these names are stored with leading / trailing spaces (' Ewing Manning Co '): names are not trimmed when saved through at least one entry point (Edit Info does trim). Automated check: AssertionError: names in displayed order: expected [ Array(8) ] to deeply equal [ Array(8) ] | I26: FAIL | J26: BUG-023 | K26: 3.5
A27: ORG-006 | B27: Organization | C27: Data integrity | D27: High | E27: Each organization appears on exactly one page of the list | F27: 1. Open /organizations pages 1 to 4 (default sort). 2. Collect the record ID of every row. | G27: No record ID appears on more than one page. | H27: Records repeat across pages (e.g. #941 'QA Bulk 0467' on pages 2 and 3; #949-#951 on pages 2 and 4), so other records are never shown. The order is not stable for rows with equal dates; a secondary sort key (ID) is missing. Automated check: AssertionError: records shown on more than one page: expected [ Array(5) ] to deeply equal [] | I27: FAIL | J27: BUG-006 | K27: 3.6
A28: ORG-007 | B28: Organization | C28: Validation | D28: High | E28: Add Organization: required fields are enforced | F28: 1. Open /organizations and click 'Add Organization'. 2. Click 'Save changes' with the form empty. | G28: Required messages for organization name, email, ID prefix, admin first name, last name, email and the consent checkbox. | H28: As expected. | I28: PASS | K28: 2.7
A29: ORG-008 | B29: Organization | C29: Validation | D29: High | E29: Add Organization: invalid formats are rejected with messages | F29: 1. Open the Add Organization form. 2. Enter a 300-character name, 'not-an-email', a non-letter ID prefix, phone 'abcdef', employees -5 and upload a .txt file as logo. 3. Click 'Save changes'. | G29: A specific message is shown under each invalid field and nothing is created. | H29: As expected. | I29: PASS | K29: 5.9
A30: ORG-009 | B30: Organization | C30: Validation | D30: Low | E30: Add Organization: logo marked as required (*) is enforced | F30: 1. Open the Add Organization form. 2. Leave 'Organization Logo*' empty and click 'Save changes'. | G30: A 'logo is required' message is shown, as the asterisk indicates. | H30: The organization is created without a logo and no message is shown. Automated check: Error: Expected the page to show text matching /logo.*(required|must)/i | I30: FAIL | J30: BUG-025 | K30: 12.6
A31: ORG-010 | B31: Organization | C31: Validation | D31: High | E31: Add Organization: an invalid Domain Prefix shows an error message | F31: 1. Open the Add Organization form. 2. Fill every field with valid data but type a 13-character Domain Prefix. 3. Tick the consent box and click 'Save changes'. | G31: The server's validation message for Domain Prefix is displayed under the field. | H31: The form stays open with no message at all and nothing is created. The server does return 'The domain prefix field must not be greater than 10 characters.', but the field has no error slot. Also reproduced with 'The domain prefix field must only contain letters and numbers.' and 'The domain has already been taken.' The field has no maxlength or hint about the 10-character limit. Automated check: Error: Expected the page to show text matching /The domain prefix field must not be greater than 10 characters\./ | I31: FAIL | J31: BUG-004 | K31: 12.3
A32: ORG-011 | B32: Organization | C32: UI | D32: Medium | E32: Add Organization: status hint matches the Organization Status switch | F32: 1. Open the Add Organization form. 2. Leave the 'Organization Status' switch off and read the hint under it. | G32: With the switch off the hint must not say the organization will be activated immediately. | H32: The hint always reads 'Organization will be activated immediately upon creation', but with the switch off the organization is created as Pending and lands in Sign Ups. Automated check: Error: Expected the page not to show "Organization will be activated immediately upon creation" | I32: FAIL | J32: BUG-017 | K32: 16.8
A33: ORG-012 | B33: Organization | C33: Functional | D33: Low | E33: Add Organization: Subscription Plan offers every available plan | F33: 1. Open the Add Organization form. 2. Open the 'Subscription Plan' dropdown. | G33: Free, Basic and Premium (the plans used elsewhere in the app) can be selected. | H33: 'Free' is the only option. Together with BUG-005 there is no way in the UI to put an organization on a paid plan. Automated check: AssertionError: expected [ 'Free' ] to be a superset of [ 'Free', 'Basic', 'Premium' ] | I33: FAIL | J33: BUG-028 | K33: 2.5
A34: ORG-013 | B34: Organization | C34: Functional | D34: High | E34: A valid organization is created as Active and counted on the dashboard | F34: 1. Note 'Total Organizations' on the dashboard. 2. Add an organization with valid data, a PNG logo and the status switch ON. 3. Search it in /organizations and /sign-ups. 4. Re-open the dashboard. | G34: Success toast; organization listed as Active on the Free plan, absent from Sign Ups, and the total increased. | H34: As expected. | I34: PASS | K34: 17.8
A35: ORG-014 | B35: Organization | C35: Validation | D35: High | E35: Duplicate organization email is rejected | F35: 1. Open the Add Organization form. 2. Re-use the email of the organization created in ORG-013 with otherwise valid data. 3. Click 'Save changes'. | G35: 'The organization email has already been taken.' is shown and nothing is created. | H35: As expected. | I35: PASS | K35: 4.9
A36: ORG-015 | B36: Organization | C36: Validation | D36: Low | E36: Admin first / last name reject digits and HTML | F36: 1. Open the Add Organization form. 2. Enter '1234' as admin first name and '<b>x</b>' as last name. 3. Click 'Save changes'. | G36: The name fields are flagged as invalid. | H36: The organization is created; emails greet the admin with 'Hello 1234' and the generated password becomes '12344569'. (The HTML is escaped on screen.) Automated check: AssertionError: fields the server rejected: expected [ 'disclaimer' ] to be a superset of [ Array(2) ] | I36: FAIL | J36: BUG-026 | K36: 5.3
A37: ORG-016 | B37: Organization | C37: Security | D37: High | E37: Admin account email does not expose a predictable plain-text password | F37: 1. Create an organization (ORG-013). 2. Open /log-viewer and find the 'Admin Account Created' email sent to the admin contact. | G37: No plain-text password is sent, or at least it cannot be derived from the admin's name and phone number. | H37: The email contains 'Password: ada4568' (lower-case first name + last four digits of the admin phone). Same pattern for every admin created (pat4571, grace4570, 12344569). The same password is re-sent on Activate, Approve and Resend Details. Automated check: AssertionError: emailed password "ada4568" is the admin's first name + last 4 phone digits: expected true to equal false | I37: FAIL | J37: BUG-002 | K37: 2.2
A38: ORG-017 | B38: Organization | C38: Functional | D38: Medium | E38: Employee ID uses the ID Prefix entered for the organization | F38: 1. Create an organization with ID Prefix 'ZQX' (ORG-013). 2. Read the 'Employee ID' in the 'Admin Account Created' email. | G38: The Employee ID starts with the configured prefix 'ZQX'. | H38: The Employee ID is 'QAM261370': the first three letters of the organization name are used instead. The 'ID prefix' column of the export is empty for all organizations. Automated check: AssertionError: Employee ID: expected 'QAM260826' to match /^ZQX/ | I38: FAIL | J38: BUG-012 | K38: 2
A39: ORG-018 | B39: Organization | C39: Integration | D39: Medium | E39: An organization created as Active gets only the onboarding emails | F39: 1. Create an organization with the status switch ON (ORG-013). 2. List the emails logged for the organization's address and for business@krystalhr.com. | G39: Welcome and admin-account emails only; no 'Your Application Has Been Received' or 'Review Required' email. | H39: The organization also gets 'Your Application Has Been Received ... we would revert within the next 24 hours', and business@krystalhr.com gets 'New Company Signup - Review Required', although nothing is left to review. Automated check: AssertionError: emails meant for pending sign-ups: expected [ Array(2) ] to deeply equal [] | I39: FAIL | J39: BUG-009 | K39: 2.3
A40: ORG-019 | B40: Organization | C40: Functional | D40: High | E40: Suspend from the list asks for confirmation and suspends the organization | F40: 1. Search the test organization in /organizations. 2. Click 'Suspend', then confirm in the 'Confirm Action' dialog. | G40: Status badge changes to Suspended and the row action becomes 'Activate'. | H40: As expected. | I40: PASS | K40: 5.3
...

Sheet Defect Log
A1: Defect ID | B1: Module | C1: Area / Feature | D1: Summary | E1: Severity | F1: Priority | G1: Type | H1: Preconditions | I1: Steps to Reproduce | J1: Expected Result | K1: Actual Result | L1: Evidence | M1: Test Cases | N1: Reproduced in this run | O1: Status
A2: BUG-001 | B2: Cross-module | C2: Log Viewer | D2: Server logs (including emails with admin passwords) can be read without logging in | E2: Critical | F2: P1 | G2: Security | H2: No session: use a private window or curl. | I2: 1. Request GET /log-viewer/api/files with header Accept: application/json. 2. Take the identifier of laravel-{date}.log from the response. 3. Request GET /log-viewer/api/logs?file={identifier}&per_page=1. | J2: Both requests are refused (redirect to /auth/login or 401/403), like the /log-viewer page itself, which does redirect. | K2: Both return HTTP 200. The first lists 105 server log files (nginx + Laravel) flagged can_download: true and can_delete: true; the second returns log entries. The Laravel log holds every email the system sends, including 'Admin Account Created' emails with plain-text passwords (BUG-002). | L2: Automated: SEC-002. Manual: curl without cookies returned 200 for both endpoints. Delete was not attempted. | M2: SEC-002 | N2: Yes | O2: Open
A3: BUG-002 | B3: Organization | C3: Add Organization / emails | D3: Admin password is emailed in plain text and is predictable (first name + last 4 phone digits) | E3: High | F3: P1 | G3: Security | H3: Logged in as tester@krystalhr.com (Super Admin). | I3: 1. Organizations > Add Organization. 2. Admin Contact: First Name 'Ada', Phone '08031234568'; complete the form and save. 3. Open /log-viewer > laravel-{date}.log and find 'Admin Account Created' sent to the admin email. | J3: A set-password link (or a random one-time password). Credentials must not be derivable from data the admin entered. | K3: The email contains 'Password: ada4568' (lower-case first name + last four digits of the admin phone). Same pattern for every admin created (pat4571, grace4570, 12344569). The same password is re-sent on Activate, Approve and Resend Details. | L3: Automated: ORG-016. Log entries 2026-10-09 14:42:33, 14:48:34, 14:51:04. | M3: ORG-016 | N3: Yes | O3: Open
A4: BUG-003 | B4: Sign Up | C4: Review Organization | D4: 'Reject' in the Review dialog does nothing | E4: High | F4: P1 | G4: Functional | H4: Logged in as tester@krystalhr.com (Super Admin). At least one pending sign-up. | I4: 1. Sign Ups > click 'Review' on a pending organization. 2. Click 'Reject'. | J4: The registration is rejected: it leaves the pending list (and the applicant is informed). | K4: Nothing happens. No request is sent to the server, no message is shown, the dialog stays open and the organization remains Pending in Sign Ups and Organizations. The button is a plain submit button inside a form with no handler. | L4: Automated: SUP-012. | M4: SUP-012 | N4: Yes | O4: Open
A5: BUG-004 | B5: Organization | C5: Add Organization | D5: Add Organization fails silently when the Domain Prefix is invalid (error is never displayed) | E5: High | F5: P1 | G5: Functional | H5: Logged in as tester@krystalhr.com (Super Admin). | I5: 1. Organizations > Add Organization. 2. Fill all fields with valid data; Domain Prefix = 'qamcdomain123' (13 characters). 3. Tick the consent box and click 'Save changes'. | J5: The Domain Prefix validation message is shown under the field (as for every other field). | K5: The form stays open with no message at all and nothing is created. The server does return 'The domain prefix field must not be greater than 10 characters.', but the field has no error slot. Also reproduced with 'The domain prefix field must only contain letters and numbers.' and 'The domain has already been taken.' The field has no maxlength or hint about the 10-character limit. | L5: Automated: ORG-010 (compares the server's message with the page). | M5: ORG-010 | N5: Yes | O5: Open
A6: BUG-005 | B6: Organization | C6: Manage > Billing and Subscription | D6: 'Change Plan' cannot be saved | E6: High | F6: P1 | G6: Functional | H6: Logged in as tester@krystalhr.com (Super Admin). An organization on the Free plan. | I6: 1. Organizations > Manage > 'Billing and Subscription'. 2. Click 'Change Plan', select 'Basic'. 3. Click 'Save changes'. | J6: The plan is updated to Basic and the dialog closes with a confirmation. | K6: Nothing happens: no request is sent, the dialog stays open, and the organization is still on Free in the list. | L6: Automated: ORG-028. | M6: ORG-028 | N6: Yes | O6: Open
A7: BUG-006 | B7: Organization | C7: Organization list (also Dashboard > Companies) | D7: The same organization appears on several pages of the list while others are skipped | E7: High | F7: P2 | G7: Data integrity | H7: Logged in as tester@krystalhr.com (Super Admin). Many organizations share the same sign-up timestamp (e.g. bulk import). | I7: 1. Open /organizations?page=2, ?page=3 and ?page=4 with the default sort (Newest). 2. Compare the organizations listed on each page. | J7: Each organization appears on exactly one page. | K7: Records repeat across pages (e.g. #941 'QA Bulk 0467' on pages 2 and 3; #949-#951 on pages 2 and 4), so other records are never shown. The order is not stable for rows with equal dates; a secondary sort key (ID) is missing. | L7: Automated: ORG-006. | M7: ORG-006 | N7: Yes | O7: Open
A8: BUG-007 | B8: Sign Up | C8: Emails on registration | D8: A pending (unapproved) organization already receives the welcome email and admin login credentials | E8: High | F8: P2 | G8: Functional | H8: Logged in as tester@krystalhr.com (Super Admin). | I8: 1. Add an organization with the 'Organization Status' switch OFF (it is created as Pending and appears in Sign Ups). 2. Open /log-viewer and list the emails for that organization. | J8: Only 'Your Application Has Been Received'. Welcome and credentials are sent after approval. | K8: Four emails at once: 'Your Application Has Been Received', 'New Company Signup - Review Required' (to business@), and also 'Welcome to KrystalHR - your organisation account has been successfully created and is ready to use' plus 'Admin Account Created' with the admin's password. The applicant is told both 'we will revert within 24 hours' and 'your account is ready'. | L8: Automated: SUP-006. Log entries 2026-10-09 14:42:33 and 14:51:01. | M8: SUP-006 | N8: Yes | O8: Open
A9: BUG-008 | B9: Sign Up | C9: Review Organization > Approve | D9: Approving a sign-up sends every onboarding email twice | E9: Medium | F9: P2 | G9: Functional | H9: Logged in as tester@krystalhr.com (Super Admin). A pending sign-up. | I9: 1. Sign Ups > Review > Approve. 2. Open /log-viewer and list the emails logged at that second. | J9: One welcome email to the organization and one account email to the admin. | K9: Two 'Welcome to KrystalHR' emails and two 'Admin Account Created' emails are sent in the same second. | L9: Automated: SUP-014. Log entries 2026-10-09 14:52:13 (4 emails). | M9: SUP-014 | N9: Yes | O9: Open
A10: BUG-009 | B10: Organization | C10: Emails on creation | D10: An organization created as Active still triggers the 'application received / review required' emails | E10: Medium | F10: P3 | G10: Functional | H10: Logged in as tester@krystalhr.com (Super Admin). | I10: 1. Add an organization with the 'Organization Status' switch ON. 2. Open /log-viewer and list the emails for that organization. | J10: Welcome and admin-account emails only: the organization is already active. | K10: The organization also gets 'Your Application Has Been Received ... we would revert within the next 24 hours', and business@krystalhr.com gets 'New Company Signup - Review Required', although nothing is left to review. | L10: Automated: ORG-018. Log entries 2026-10-09 14:45:06. | M10: ORG-018 | N10: Yes | O10: Open
A11: BUG-010 | B11: Organization | C11: Manage > Organization Details; Sign Ups > Review | D11: Industry is shown as a number instead of its name | E11: Medium | F11: P2 | G11: UI / Data | H11: Logged in as tester@krystalhr.com (Super Admin). An organization created with industry 'Technology'. | I11: 1. Organizations > Manage on that organization and read 'Industry'. 2. For a pending one: Sign Ups > Review and read 'Industry'. | J11: 'Technology' (the option chosen at creation). | K11: The field shows the internal ID: '1' for Technology, '2' for Fashion, '4' for Finance. | L11: Automated: ORG-022, SUP-011. | M11: ORG-022, SUP-011 | N11: Yes | O11: Open
A12: BUG-011 | B12: Organization | C12: Manage > Edit Info | D12: Edit Info offers a different industry list and preselects 'Photography' | E12: Medium | F12: P2 | G12: Functional | H12: Logged in as tester@krystalhr.com (Super Admin). An organization created with industry 'Technology'. | I12: 1. Organizations > Manage > 'Edit Info'. 2. Open the Industry dropdown. | J12: The 15 industries of the Add form (Technology, Fashion, Healthcare, ...) with the saved one selected. | K12: A different list is offered (Photography, Design services, Web development, Accounting, Legal services, Consulting, Other) and 'Photography' is preselected. The saved industry cannot be kept visible or re-selected, and choosing an option stores a text value where the rest of the app uses numeric IDs. | L12: Automated: ORG-023. | M12: ORG-023 | N12: Yes | O12: Open
... A34: BUG-033 | B34: Announcements | C34: Announcement list | D34: Search only matches the title, not the sender | E34: Low | F34: P4 | G34: Enhancement | H34: Logged in as tester@krystalhr.com (Super Admin). | I34: 1. Open /announcements. 2. Search 'support@krystalhr.com' (a value shown in the Sender column). | J34: Announcements from that sender. | K34: 'No announcements found.' | L34: Automated: ANN-003. | M34: ANN-003 | N34: Yes | O34: Open
A35: BUG-034 | B35: Organization | C35: Validation messages (Edit Info, Add New Admin, Contact Organization) | D35: Validation messages expose internal field names | E35: Low | F35: P4 | G35: UI | H35: Logged in as tester@krystalhr.com (Super Admin). | I35: 1. Manage > Edit Info: enter -9 employees and Save. 2. Manage > Admins > Add New Admin: click 'Create User' empty. 3. Sign Ups > Contact: click 'Send Email' empty. | J35: Plain-language messages ('Number of employees must be at least 1'). | K35: 'The edit.number of employees field must be at least 1.', 'The admin.first name field is required.', 'The contact.message field is required.' | L35: Exploratory; visible in the screenshots of ORG-024, ORG-026 and SUP-007. | N35: Manual (exploratory) | O35: Open
A36: BUG-035 | B36: Sign Up | C36: Contact Organization | D36: Message placeholder is copied from a recruitment screen | E36: Low | F36: P4 | G36: UI | H36: Logged in as tester@krystalhr.com (Super Admin). | I36: 1. Sign Ups > Contact and read the Message placeholder. | J36: A placeholder about contacting a registering organization. | K36: 'Provide interview details, including format, expectations, date, and time, along with any important instructions for candidates.' The upload is also labelled 'Descriptive Image'. | L36: Exploratory. | N36: Manual (exploratory) | O36: Open
A37: BUG-036 | B37: Organization | C37: Manage page header | D37: Activate / Suspend on the Manage page act without confirmation | E37: Low | F37: P4 | G37: UI | H37: Logged in as tester@krystalhr.com (Super Admin). | I37: 1. Organizations > Manage. 2. Click 'Suspend' (or 'Activate') in the header. | J37: The same 'Confirm Action' dialog used by the list. | K37: The status changes immediately on one click. | L37: Exploratory. | N37: Manual (exploratory) | O37: Open
A38: BUG-037 | B38: Organization | C38: Add Organization | D38: Emails on domains without mail records are rejected as 'must be a valid email address' | E38: Low | F38: P4 | G38: Validation | H38: Logged in as tester@krystalhr.com (Super Admin). | I38: 1. Add an organization with email 'name@example.com'. | J38: Accepted, or a message that explains the domain cannot receive mail. | K38: 'The organization email field must be a valid email address.' although the address is well-formed; the same form accepts '@mailinator.com'. Existing bulk-created organizations do have '@example.com' addresses, so entry points disagree. | L38: Exploratory. | N38: Manual (exploratory) | O38: Open
A39: BUG-038 | B39: Organization | C39: Import CSV | D39: Import error toast does not say which rows failed and omits some errors | E39: Low | F39: P4 | G39: UI | H39: Logged in as tester@krystalhr.com (Super Admin). | I39: 1. Import a CSV with one valid row, one row with a bad email and -4 employees, and one row re-using an existing domain prefix. | J39: A per-row report (row number, field, reason). | K39: Toasts '1 companies created successfully.' and '2 row(s) failed to import.The email field must be a valid email address., The number of employees field must be at least 1.' No row numbers are given and the duplicate-domain reason is missing. | L39: Exploratory. | N39: Manual (exploratory) | O39: Open
A40: BUG-039 | B40: Sign Up | C40: Emails on registration | D40: 'New Company Signup' email is sometimes sent with an empty Admin Name | E40: Low | F40: P4 | G40: Functional | H40: Logged in as tester@krystalhr.com (Super Admin). | I40: 1. Add several pending organizations. 2. Read the 'New Company Signup - Review Required' emails sent to business@krystalhr.com. | J40: 'Admin Name: Pat Pending'. | K40: Intermittent (1 of 4 observed): 'Admin Name:' is blank. In that case the admin account email was logged three seconds after the notification, so the notification appears to be built before the admin exists. | L40: Exploratory. Log entry 2026-10-09 14:51:01. | N40: Manual (exploratory) | O40: Open

Sheet Successes
A1: Module | B1: Test ID | C1: What works | D1: Verified behaviour | E1: Type
A2: Dashboard | B2: DSH-001 | C2: Dashboard shows the three KPI cards with numeric values | D2: 'Total Organizations', 'Pending Organizations' and 'Total Users' cards each show a whole number. | E2: UI
A3: Dashboard | B3: DSH-002 | C3: Side menu lists the four modules and each link opens its page | D3: Each click opens /organizations, /sign-ups, /announcements and /dashboard respectively. | E3: Functional
A4: Dashboard | B4: DSH-003 | C4: 'Total Organizations' matches the number of records in the organization list | D4: The computed record count equals the KPI card. | E4: Data integrity
A5: Dashboard | B5: DSH-004 | C5: 'Pending Organizations' matches the number of pending sign-ups | D5: The number of sign-up records equals the KPI card. | E5: Data integrity
A6: Dashboard | B6: DSH-005 | C6: Organization Status chart is consistent with the KPI cards | D6: Shares add up to 100% and the Pending share equals Pending / Total from the cards. | E6: Data integrity
A7: Dashboard | B7: DSH-009 | C7: Companies table on the dashboard shows its columns and ten rows | D7: Columns Organizations, Plan, Sign Up Date, Employees, Date Updated, Status, Action are shown with 10 rows and pagination. | E7: UI
A8: Dashboard | B8: DSH-010 | C8: Dashboard search filters companies and shows an empty-state message | D8: Only matching companies are listed; with no match 'No companies found.' is shown. | E8: Functional
A9: Dashboard | B9: DSH-011 | C9: Light / dark appearance toggle switches the theme | D9: The page switches to the dark theme and back to the light theme. | E9: UI
A10: Dashboard | B10: DSH-012 | C10: 'Add Organization' can be opened from the dashboard | D10: The 'Add New Organization' form opens. | E10: Functional
A11: Organization | B11: ORG-001 | C11: Organizations page lists companies with columns, actions and pagination | D11: Ten rows with Plan, dates, Status badge, Activate/Suspend and Manage actions, plus pagination, Search, Export CSV, Import CSV and Sort. | E11: UI
A12: Organization | B12: ORG-002 | C12: Search finds an organization regardless of letter case | D12: The organization is listed; the non-matching search shows 'No companies found.' | E12: Functional
... A62: Cross-module | B62: SEC-005 | C62: HTML in organization names is displayed as text | D62: Names are rendered as plain text; no dialog is triggered and no script element is injected into the table. | E62: Security

Sheet Evidence
A1: Evidence | B1: End-state screenshot of each failed test case, grouped by defect. Emails were verified in /log-viewer (laravel-{date}.log).
A3: BUG-001 | B3: Critical | Cross-module | Server logs (including emails with admin passwords) can be read without logging in
A4: SEC-002 | B4: Log viewer API is not readable without logging in (cypress/screenshots/05-cross-module.cy.js/evidence/SEC-002.png)
A28: BUG-002 | B28: High | Organization | Admin password is emailed in plain text and is predictable (first name + last 4 phone digits)
A29: ORG-016 | B29: Admin account email does not expose a predictable plain-text password (cypress/screenshots/02-organization.cy.js/evidence/ORG-016.png)
A53: BUG-003 | B53: High | Sign Up | 'Reject' in the Review dialog does nothing
A54: SUP-012 | B54: Reject removes the registration from the pending list (cypress/screenshots/03-signup.cy.js/evidence/SUP-012.png)
A78: BUG-004 | B78: High | Organization | Add Organization fails silently when the Domain Prefix is invalid (error is never displayed)
A79: ORG-010 | B79: Add Organization: an invalid Domain Prefix shows an error message (cypress/screenshots/evidence/ORG-010.png)
A103: BUG-005 | B103: High | Organization | 'Change Plan' cannot be saved
A104: ORG-028 | B104: Billing tab: Change Plan saves the selected plan (cypress/screenshots/02-organization.cy.js/evidence/ORG-028.png)
A128: BUG-006 | B128: High | Organization | The same organization appears on several pages of the list while others are skipped
... A873: ANN-003 | B873: Search also matches the sender address (cypress/screenshots/04-announcements.cy.js/evidence/ANN-003.png)

Sheet Scope & Notes
A1: Scope | B1: Side-menu modules named in the brief: Dashboard, Organization (list, Add Organization, Manage: details / admins / billing, CSV export and import), Sign Up (list, Contact, Review: approve / reject) and Announcements (list, create, details). Login / logout were covered because every module depends on them.
A2: Out of scope | B2: Tenant (organization) sites, Settings, load / performance testing, and destructive checks on the log viewer (delete was never attempted).
A3: Approach | B3: 1. Exploratory session through every screen and action of the four modules, including negative input, boundary values and the emails each action produces. 2. Every scenario was then written as an automated Cypress test (cypress/e2e) so the results in this workbook come from an actual run, not from notes. 3. A test FAILS when the application does not do what the 'Expected Result' column says; each failure is linked to a defect.
A4: Expected results | B4: No requirements document was provided. Expected results are based on the application's own labels and messages, consistency between screens, and common practice. Items that need a product decision say so in the defect (e.g. BUG-020).
A5: Severity scale | B5: Critical: security or data exposure, or a module is unusable. High: a main function fails with no workaround, or data shown is wrong. Medium: a function is impaired or misleading but a workaround exists. Low: cosmetic, wording or minor usability.
A6: Shared environment | B6: Staging is shared with other testers and its data changed during testing (organization count moved from 946 to 950+). Counts quoted in defects are the values seen at the time. Row actions in the automated suite are only ever performed on records the suite created.
A7: Test data created | B7: Organizations, admins and announcements created by testing are prefixed 'QAMC' and use @mailinator.com addresses. There is no delete function, so they remain on staging. This run: QAMC Active 1417472 (#1012), QAMC Pending 1553763 (#1013), QAMC Reject 1635382 (#1014).
A8: Emails | B8: Staging does not deliver email. Each expected email was looked up in /log-viewer > laravel-{date}.log by recipient / subject.
A9: Recommended fix order | B9: 1. BUG-001 put the log viewer API behind authentication, then rotate anything exposed. 2. BUG-002 replace emailed predictable passwords with a set-password link. 3. BUG-003, BUG-004, BUG-005 restore Reject, Domain Prefix error display and Change Plan. 4. BUG-006, BUG-007, BUG-008 list ordering and the registration / approval emails. 5. Medium and Low items as scheduled.
A10: Reproducing this report | B10: npm install, then `npm run cy:run` (full suite, about 12 minutes) and `npm run report`. `npm test` does both.
